Workbook

Sheet Summary
A1: Template | B1: Delivery Department KPI
A2: Period Start (YYYY-MM-DD) | B2: 46023
A3: Period End (YYYY-MM-DD) | B3: 46053
A5: Goal Comments
A6: Goal Key | B6: Goal Name | C6: Comment
A7: billability_utilization | B7: Billability & Utilization
A8: delivery_excellence | B8: Delivery Excellence
A9: quality_process | B9: Quality & Process
A10: value_client | B10: Value Add & Client Satisfaction

Sheet Raw Delivery Log
A1: Month / Period
A2: Sr No | B2: Ticket/Task ID | C2: Project/Module | D2: Issue Description | E2: Issue Date | F2: Due Date | G2: Delivery Date | H2: Delivered? (Y/N) | I2: Rework Required? (Y/N) | J2: Rework Count | K2: Escalated? (Y/N) | L2: Escalation Level | M2: Post-Delivery Defect? (Y/N) | N2: Defect Count | O2: Type | P2: Root Cause | Q2: Reference Link | R2: FTR Flag | S2: ESC Flag | T2: PDD Flag | U2: Scope Request? (Y/N) | V2: Approved Scope Change? (Y/N) | W2: Milestone? (Y/N) | X2: Milestone On Time? (Y/N) | Y2: Formal Change Logged? (Y/N) | Z2: Automation Used? (Y/N) | AA2: Additional Initiative? (Y/N) | AB2: CSAT Score
A3: 1 | B3: M0093 | C3: M0093_SharePoint_to_DMP | D3: File Management Issue | E3: 46051 | F3: 46056 | G3: 46055 | H3: Y | I3: N | J3: 0 | K3: Y | L3: None | M3: N | N3: 0 | O3: Bug | P3: Incorrect Mappings in RestClient Step | Q3: M0093 | R3: =IF(AND(H3="Y",I3<>"Y"),1,0) | S3: =IF(K3="Y",1,0) | T3: =IF(M3="Y",1,0) | U3: =IF(I3="Y","Y","N") | V3: =IF(U3="Y","Y","N") | W3: =IF(H3="Y","Y","N") | X3: =IF(AND(W3="Y",G3<=F3),"Y","N") | Y3: =IF(U3="Y","Y","N") | Z3: =IF(ISNUMBER(SEARCH("autom",LOWER(P3))),"Y","N") | AA3: =IF(LOWER(O3)="value add","Y","N") | AB3: =IF(AA3="Y",5,"")
A4: 2 | B4: 564 | C4: M0098_DMP_to_FoodLink | D4: Scratch Development | E4: 46045 | F4: 46052 | G4: 46052 | H4: Y | I4: Y | J4: 2 | K4: N | L4: None | M4: N | N4: 0 | O4: Bug | P4: Requirement Change | Q4: TORIDOLL_INTERNAL-564 | R4: =IF(AND(H4="Y",I4<>"Y"),1,0) | S4: =IF(K4="Y",1,0) | T4: =IF(M4="Y",1,0) | U4: =IF(I4="Y","Y","N") | V4: =IF(U4="Y","Y","N") | W4: =IF(H4="Y","Y","N") | X4: =IF(AND(W4="Y",G4<=F4),"Y","N") | Y4: =IF(U4="Y","Y","N") | Z4: =IF(ISNUMBER(SEARCH("autom",LOWER(P4))),"Y","N") | AA4: =IF(LOWER(O4)="value add","Y","N") | AB4: =IF(AA4="Y",5,"")
A5: 3 | B5: 261 | C5: M0025_JNAL_DMPtoBlackLine | D5: DDL for creating internal TB is not for MySQL | E5: 46057 | F5: 46059 | G5: 46059 | H5: Y | I5: N | J5: 0 | K5: N | L5: None | M5: N | N5: 0 | O5: Bug | P5: - | Q5: TORIDOLL_INTERNAL-261 | R5: =IF(AND(H5="Y",I5<>"Y"),1,0) | S5: =IF(K5="Y",1,0) | T5: =IF(M5="Y",1,0) | U5: =IF(I5="Y","Y","N") | V5: =IF(U5="Y","Y","N") | W5: =IF(H5="Y","Y","N") | X5: =IF(AND(W5="Y",G5<=F5),"Y","N") | Y5: =IF(U5="Y","Y","N") | Z5: =IF(ISNUMBER(SEARCH("autom",LOWER(P5))),"Y","N") | AA5: =IF(LOWER(O5)="value add","Y","N") | AB5: =IF(AA5="Y",5,"")
A6: 4 | B6: 641 | C6: M0025_JNAL_DMPtoBlackLine | D6: Unable to get S3 in bulk | E6: 46057 | F6: 46059 | G6: 46059 | H6: Y | I6: N | J6: 0 | K6: N | L6: None | M6: N | N6: 0 | O6: Bug | P6: - | Q6: TORIDOLL_INTERNAL-641 | R6: =IF(AND(H6="Y",I6<>"Y"),1,0) | S6: =IF(K6="Y",1,0) | T6: =IF(M6="Y",1,0) | U6: =IF(I6="Y","Y","N") | V6: =IF(U6="Y","Y","N") | W6: =IF(H6="Y","Y","N") | X6: =IF(AND(W6="Y",G6<=F6),"Y","N") | Y6: =IF(U6="Y","Y","N") | Z6: =IF(ISNUMBER(SEARCH("autom",LOWER(P6))),"Y","N") | AA6: =IF(LOWER(O6)="value add","Y","N") | AB6: =IF(AA6="Y",5,"")
A7: 5 | B7: 521 | C7: ngc | E7: 46057 | F7: 46061 | G7: 46059 | H7: Y | I7: N | J7: 0 | K7: N | L7: None | M7: Y | N7: 0 | O7: Value Add | R7: =IF(AND(H7="Y",I7<>"Y"),1,0) | S7: =IF(K7="Y",1,0) | T7: =IF(M7="Y",1,0) | U7: =IF(I7="Y","Y","N") | V7: =IF(U7="Y","Y","N") | W7: =IF(H7="Y","Y","N") | X7: =IF(AND(W7="Y",G7<=F7),"Y","N") | Y7: =IF(U7="Y","Y","N") | Z7: =IF(ISNUMBER(SEARCH("autom",LOWER(P7))),"Y","N") | AA7: =IF(LOWER(O7)="value add","Y","N") | AB7: =IF(AA7="Y",5,"")
A8: 6 | R8: =IF(AND(H8="Y",I8<>"Y"),1,0) | S8: =IF(K8="Y",1,0) | T8: =IF(M8="Y",1,0) | U8: =IF(I8="Y","Y","N") | V8: =IF(U8="Y","Y","N") | W8: =IF(H8="Y","Y","N") | X8: =IF(AND(W8="Y",G8<=F8),"Y","N") | Y8: =IF(U8="Y","Y","N") | Z8: =IF(ISNUMBER(SEARCH("autom",LOWER(P8))),"Y","N") | AA8: =IF(LOWER(O8)="value add","Y","N") | AB8: =IF(AA8="Y",5,"")
A9: 7 | R9: =IF(AND(H9="Y",I9<>"Y"),1,0) | S9: =IF(K9="Y",1,0) | T9: =IF(M9="Y",1,0) | U9: =IF(I9="Y","Y","N") | V9: =IF(U9="Y","Y","N") | W9: =IF(H9="Y","Y","N") | X9: =IF(AND(W9="Y",G9<=F9),"Y","N") | Y9: =IF(U9="Y","Y","N") | Z9: =IF(ISNUMBER(SEARCH("autom",LOWER(P9))),"Y","N") | AA9: =IF(LOWER(O9)="value add","Y","N") | AB9: =IF(AA9="Y",5,"")
A10: 8 | R10: =IF(AND(H10="Y",I10<>"Y"),1,0) | S10: =IF(K10="Y",1,0) | T10: =IF(M10="Y",1,0) | U10: =IF(I10="Y","Y","N") | V10: =IF(U10="Y","Y","N") | W10: =IF(H10="Y","Y","N") | X10: =IF(AND(W10="Y",G10<=F10),"Y","N") | Y10: =IF(U10="Y","Y","N") | Z10: =IF(ISNUMBER(SEARCH("autom",LOWER(P10))),"Y","N") | AA10: =IF(LOWER(O10)="value add","Y","N") | AB10: =IF(AA10="Y",5,"")
A11: 9 | R11: =IF(AND(H11="Y",I11<>"Y"),1,0) | S11: =IF(K11="Y",1,0) | T11: =IF(M11="Y",1,0) | U11: =IF(I11="Y","Y","N") | V11: =IF(U11="Y","Y","N") | W11: =IF(H11="Y","Y","N") | X11: =IF(AND(W11="Y",G11<=F11),"Y","N") | Y11: =IF(U11="Y","Y","N") | Z11: =IF(ISNUMBER(SEARCH("autom",LOWER(P11))),"Y","N") | AA11: =IF(LOWER(O11)="value add","Y","N") | AB11: =IF(AA11="Y",5,"")
A12: 10 | R12: =IF(AND(H12="Y",I12<>"Y"),1,0) | S12: =IF(K12="Y",1,0) | T12: =IF(M12="Y",1,0) | U12: =IF(I12="Y","Y","N") | V12: =IF(U12="Y","Y","N") | W12: =IF(H12="Y","Y","N") | X12: =IF(AND(W12="Y",G12<=F12),"Y","N") | Y12: =IF(U12="Y","Y","N") | Z12: =IF(ISNUMBER(SEARCH("autom",LOWER(P12))),"Y","N") | AA12: =IF(LOWER(O12)="value add","Y","N") | AB12: =IF(AA12="Y",5,"")
A13: 11 | R13: =IF(AND(H13="Y",I13<>"Y"),1,0) | S13: =IF(K13="Y",1,0) | T13: =IF(M13="Y",1,0) | U13: =IF(I13="Y","Y","N") | V13: =IF(U13="Y","Y","N") | W13: =IF(H13="Y","Y","N") | X13: =IF(AND(W13="Y",G13<=F13),"Y","N") | Y13: =IF(U13="Y","Y","N") | Z13: =IF(ISNUMBER(SEARCH("autom",LOWER(P13))),"Y","N") | AA13: =IF(LOWER(O13)="value add","Y","N") | AB13: =IF(AA13="Y",5,"")
A14: 12 | R14: =IF(AND(H14="Y",I14<>"Y"),1,0) | S14: =IF(K14="Y",1,0) | T14: =IF(M14="Y",1,0) | U14: =IF(I14="Y","Y","N") | V14: =IF(U14="Y","Y","N") | W14: =IF(H14="Y","Y","N") | X14: =IF(AND(W14="Y",G14<=F14),"Y","N") | Y14: =IF(U14="Y","Y","N") | Z14: =IF(ISNUMBER(SEARCH("autom",LOWER(P14))),"Y","N") | AA14: =IF(LOWER(O14)="value add","Y","N") | AB14: =IF(AA14="Y",5,"")
A15: 13 | R15: =IF(AND(H15="Y",I15<>"Y"),1,0) | S15: =IF(K15="Y",1,0) | T15: =IF(M15="Y",1,0) | U15: =IF(I15="Y","Y","N") | V15: =IF(U15="Y","Y","N") | W15: =IF(H15="Y","Y","N") | X15: =IF(AND(W15="Y",G15<=F15),"Y","N") | Y15: =IF(U15="Y","Y","N") | Z15: =IF(ISNUMBER(SEARCH("autom",LOWER(P15))),"Y","N") | AA15: =IF(LOWER(O15)="value add","Y","N") | AB15: =IF(AA15="Y",5,"")
A16: 14 | R16: =IF(AND(H16="Y",I16<>"Y"),1,0) | S16: =IF(K16="Y",1,0) | T16: =IF(M16="Y",1,0) | U16: =IF(I16="Y","Y","N") | V16: =IF(U16="Y","Y","N") | W16: =IF(H16="Y","Y","N") | X16: =IF(AND(W16="Y",G16<=F16),"Y","N") | Y16: =IF(U16="Y","Y","N") | Z16: =IF(ISNUMBER(SEARCH("autom",LOWER(P16))),"Y","N") | AA16: =IF(LOWER(O16)="value add","Y","N") | AB16: =IF(AA16="Y",5,"")
A17: 15 | R17: =IF(AND(H17="Y",I17<>"Y"),1,0) | S17: =IF(K17="Y",1,0) | T17: =IF(M17="Y",1,0) | U17: =IF(I17="Y","Y","N") | V17: =IF(U17="Y","Y","N") | W17: =IF(H17="Y","Y","N") | X17: =IF(AND(W17="Y",G17<=F17),"Y","N") | Y17: =IF(U17="Y","Y","N") | Z17: =IF(ISNUMBER(SEARCH("autom",LOWER(P17))),"Y","N") | AA17: =IF(LOWER(O17)="value add","Y","N") | AB17: =IF(AA17="Y",5,"")
A18: 16 | R18: =IF(AND(H18="Y",I18<>"Y"),1,0) | S18: =IF(K18="Y",1,0) | T18: =IF(M18="Y",1,0) | U18: =IF(I18="Y","Y","N") | V18: =IF(U18="Y","Y","N") | W18: =IF(H18="Y","Y","N") | X18: =IF(AND(W18="Y",G18<=F18),"Y","N") | Y18: =IF(U18="Y","Y","N") | Z18: =IF(ISNUMBER(SEARCH("autom",LOWER(P18))),"Y","N") | AA18: =IF(LOWER(O18)="value add","Y","N") | AB18: =IF(AA18="Y",5,"")
A19: 17 | R19: =IF(AND(H19="Y",I19<>"Y"),1,0) | S19: =IF(K19="Y",1,0) | T19: =IF(M19="Y",1,0) | U19: =IF(I19="Y","Y","N") | V19: =IF(U19="Y","Y","N") | W19: =IF(H19="Y","Y","N") | X19: =IF(AND(W19="Y",G19<=F19),"Y","N") | Y19: =IF(U19="Y","Y","N") | Z19: =IF(ISNUMBER(SEARCH("autom",LOWER(P19))),"Y","N") | AA19: =IF(LOWER(O19)="value add","Y","N") | AB19: =IF(AA19="Y",5,"")
... A39: 37 | R39: =IF(AND(H39="Y",I39<>"Y"),1,0) | S39: =IF(K39="Y",1,0) | T39: =IF(M39="Y",1,0) | U39: =IF(I39="Y","Y","N") | V39: =IF(U39="Y","Y","N") | W39: =IF(H39="Y","Y","N") | X39: =IF(AND(W39="Y",G39<=F39),"Y","N") | Y39: =IF(U39="Y","Y","N") | Z39: =IF(ISNUMBER(SEARCH("autom",LOWER(P39))),"Y","N") | AA39: =IF(LOWER(O39)="value add","Y","N") | AB39: =IF(AA39="Y",5,"")
A41: Total Delivered (Y) | B41: =COUNTIFS(H3:H39,"Y") | C41: Count
A42: First Time Right Count | B42: =SUM(R3:R39) | C42: Count
A43: Escalation Count | B43: =COUNTIFS(K3:K39,"Y") | C43: Count
A44: Post-Delivery Defect Count | B44: =COUNTIFS(M3:M39,"Y") | C44: Count
A45: First Time Right (%) | B45: =IF(B41=0,0,ROUND((B42/B41)*100,2)) | C45: %
A46: Escalation Rate (%) | B46: =IF(B41=0,0,ROUND((B43/B41)*100,2)) | C46: %
A47: Post-Delivery Defect Rate (%) | B47: =IF(B41=0,0,ROUND((B44/B41)*100,2)) | C47: %
A48: Total Scope Requests (Proxy) | B48: =COUNTIFS(U3:U39,"Y") | C48: Count
A49: Approved Scope Changes (Proxy) | B49: =COUNTIFS(V3:V39,"Y") | C49: Count
A50: Total Milestones (Proxy) | B50: =COUNTIFS(W3:W39,"Y") | C50: Count
A51: Milestones On-Time (Proxy) | B51: =COUNTIFS(X3:X39,"Y") | C51: Count
A52: Total Projects Delivered | B52: =COUNTIFS(H3:H39,"Y") | C52: Count
A53: Projects On-Time/Budget | B53: =COUNTIFS(H3:H39,"Y",G3:G39,"<="&F3:F39) | C53: Count
A54: Rework Count | B54: =SUM(J3:J39) | C54: Count
A55: Formal Changes (Proxy) | B55: =COUNTIFS(Y3:Y39,"Y") | C55: Count
A56: Total Changes (Proxy) | B56: =B48 | C56: Count
A57: Total Projects (Row Count) | B57: =COUNTIFS(C3:C39,"<>") | C57: Count
A58: Automated Projects (Proxy) | B58: =COUNTIFS(Z3:Z39,"Y") | C58: Count
A59: Additional Initiatives | B59: =COUNTIFS(AA3:AA39,"Y") | C59: Count
A60: CSAT Total Score (Proxy) | B60: =SUM(AB3:AB39) | C60: Score
...

Sheet Billability & Utilization
A1: Goal Key | B1: billability_utilization
A2: Goal Name | B2: Billability & Utilization
A3: Description | B3: Ensure optimal utilization of delivery resources and maximize billable contribution.
A4: Goal Comment
A6: Metric Key | B6: Metric Label | C6: Type | D6: Required | E6: Definition | F6: Value | G6: Comment
A7: bu_billable_hours | B7: Billable Hours (Input) | C7: NUMBER | D7: Yes | F7: 8
A8: bu_available_hours | B8: Available Hours (Input) | C8: NUMBER | D8: Yes | F8: 50
A9: bu_total_working_hours | B9: Total Working Hours (Input) | C9: NUMBER | D9: Yes | F9: 120
A10: utilization_rate | B10: Utilization Rate (%) | C10: PERCENT | D10: Auto | E10: Measures the percentage of available working hours that are spent on billable activities. | F10: =IFERROR((F7 / F8) * 100, "")
A11: billability_rate | B11: Billability Rate (%) | C11: PERCENT | D11: Auto | E11: Measures percentage of total working time that is billable to clients. | F11: =IFERROR((F7 / F9) * 100, "")

Sheet Delivery Excellence
A1: Goal Key | B1: delivery_excellence
A2: Goal Name | B2: Delivery Excellence
A3: Description | B3: Ensure projects are delivered on time, within budget, and with high quality.
A4: Goal Comment
A6: Metric Key | B6: Metric Label | C6: Type | D6: Required | E6: Definition | F6: Value | G6: Comment
A7: de_projects_on_time_budget | B7: Projects Delivered On Time & Budget (Input) | C7: NUMBER | D7: Yes | F7: ='Raw Delivery Log'!B53
A8: de_total_projects_delivered | B8: Total Projects Delivered (Input) | C8: NUMBER | D8: Yes | F8: ='Raw Delivery Log'!B52
A9: de_approved_scope_changes | B9: Approved Scope Changes (Input) | C9: NUMBER | D9: Yes | F9: ='Raw Delivery Log'!B49
A10: de_total_scope_requests | B10: Total Scope Change Requests (Input) | C10: NUMBER | D10: Yes | F10: ='Raw Delivery Log'!B48
A11: de_deliverables_accepted | B11: Deliverables Accepted Without Rework (Input) | C11: NUMBER | D11: Auto (Raw Sheet) | F11: ='Raw Delivery Log'!B42
A12: de_total_deliverables | B12: Total Deliverables (Input) | C12: NUMBER | D12: Auto (Raw Sheet) | F12: ='Raw Delivery Log'!B41
A13: de_milestones_on_time | B13: Milestones Completed On Time (Input) | C13: NUMBER | D13: Yes | F13: ='Raw Delivery Log'!B51
A14: de_total_milestones | B14: Total Milestones (Input) | C14: NUMBER | D14: Yes | F14: ='Raw Delivery Log'!B50
A15: de_escalation_count | B15: Escalation Count (Input) | C15: NUMBER | D15: Auto (Raw Sheet) | F15: ='Raw Delivery Log'!B43
A16: de_post_delivery_defects | B16: Post Delivery Defects (Input) | C16: NUMBER | D16: Auto (Raw Sheet) | F16: ='Raw Delivery Log'!B44
A17: de_total_deliveries | B17: Total Deliveries (Input) | C17: NUMBER | D17: Auto (Raw Sheet) | F17: ='Raw Delivery Log'!B41
A18: on_time_delivery | B18: On-Time & On-Budget Delivery (%) | C18: PERCENT | D18: Auto | E18: Measures percentage of projects delivered on time and within approved budget. | F18: =IFERROR((F7 / F8) * 100, "")
A19: scope_change_control | B19: Scope Change Control Effectiveness (%) | C19: PERCENT | D19: Auto | E19: Measures effectiveness of managing and controlling project scope changes. | F19: =IFERROR((F9 / F10) * 100, "")
A20: first_time_right | B20: First Time Right (%) | C20: PERCENT | D20: Auto | E20: Measures percentage of deliverables accepted by client without requiring rework. | F20: =IFERROR((F11 / F12) * 100, "")
A21: schedule_adherence | B21: Schedule Adherence (%) | C21: PERCENT | D21: Auto | E21: Measures how well project milestones are delivered as per planned schedule. | F21: =IFERROR((F13 / F14) * 100, "")
A22: escalation_rate | B22: Escalation Rate (Count) | C22: NUMBER | D22: Auto | E22: Measures number of client escalations during delivery period. | F22: =IFERROR(F15, "")
A23: post_delivery_defect_rate | B23: Post Delivery Defect Rate (%) | C23: PERCENT | D23: Auto | E23: Measures defects reported after delivery completion. | F23: =IFERROR((F16 / F17) * 100, "")

Sheet Quality & Process
A1: Goal Key | B1: quality_process
A2: Goal Name | B2: Quality & Process
A3: Description | B3: Ensure adherence to defined processes and maintain high quality standards.
A4: Goal Comment
A6: Metric Key | B6: Metric Label | C6: Type | D6: Required | E6: Definition | F6: Value | G6: Comment
A7: qp_rework_count | B7: Deliverables Requiring Rework (Input) | C7: NUMBER | D7: Yes | F7: ='Raw Delivery Log'!B54
A8: qp_total_deliverables | B8: Total Deliverables (Input) - Quality | C8: NUMBER | D8: Yes | F8: ='Raw Delivery Log'!B41
A9: qp_compliant_deliveries | B9: Process Compliant Deliveries (Input) | C9: NUMBER | D9: Yes | F9: ='Raw Delivery Log'!B62
A10: qp_total_deliveries | B10: Total Deliveries (Input) - Process | C10: NUMBER | D10: Yes | F10: ='Raw Delivery Log'!B41
A11: qp_formal_changes | B11: Formally Managed Changes (Input) | C11: NUMBER | D11: Yes | F11: ='Raw Delivery Log'!B55
A12: qp_total_changes | B12: Total Changes (Input) | C12: NUMBER | D12: Yes | F12: ='Raw Delivery Log'!B56
A13: qp_automated_projects | B13: Projects Using Automation (Input) | C13: NUMBER | D13: Yes | F13: ='Raw Delivery Log'!B58
A14: qp_total_projects | B14: Total Projects (Input) | C14: NUMBER | D14: Yes | F14: ='Raw Delivery Log'!B57
A15: delivery_error_rework_rate | B15: Delivery Error / Rework Rate (%) | C15: PERCENT | D15: Auto | E15: Measures percentage of deliverables requiring correction or rework. | F15: =IFERROR((F7 / F8) * 100, "")
A16: process_compliance_rate | B16: Process Compliance Rate (%) | C16: PERCENT | D16: Auto | E16: Measures adherence to defined SOPs and delivery processes. | F16: =IFERROR((F9 / F10) * 100, "")
A17: change_management_adherence | B17: Change Management Adherence (%) | C17: PERCENT | D17: Auto | E17: Measures percentage of changes handled using formal change management process. | F17: =IFERROR((F11 / F12) * 100, "")
A18: automation_adoption | B18: Automation Adoption (%) | C18: PERCENT | D18: Auto | E18: Measures usage of automation in delivery activities. | F18: =IFERROR((F13 / F14) * 100, "")

Sheet Value Add & Client Satisfaction
A1: Goal Key | B1: value_client
A2: Goal Name | B2: Value Add & Client Satisfaction
A3: Description | B3: Deliver additional business value and ensure high client satisfaction.
A4: Goal Comment
A6: Metric Key | B6: Metric Label | C6: Type | D6: Required | E6: Definition | F6: Value | G6: Comment
A7: vc_additional_initiatives | B7: Additional Initiatives Completed (Input) | C7: NUMBER | D7: Yes | F7: ='Raw Delivery Log'!B59
A8: vc_total_score | B8: Total Client Ratings Score (Input) | C8: NUMBER | D8: Yes | F8: ='Raw Delivery Log'!B60
A9: vc_total_responses | B9: Total Client Responses (Input) | C9: NUMBER | D9: Yes | F9: ='Raw Delivery Log'!B61
A10: additional_initiatives_delivered | B10: Additional Initiatives Delivered (Count) | C10: NUMBER | D10: Auto | E10: Measures number of additional value-added initiatives beyond planned delivery. | F10: =IFERROR(F7, "")
A11: csat_score | B11: Client Satisfaction Score (CSAT) | C11: NUMBER | D11: Auto | E11: Measures client satisfaction level based on feedback ratings. | F11: =IFERROR((F8 / F9), "")

Sheet AutoFill Notes
A1: Current Template Raw-Driven AutoFill Sample (No code changes)
A2: Purpose: Fill Raw Delivery Log only; Delivery/Quality/Value metrics auto-fill via formulas.
A3: File source: delivery-department-kpi (3).xlsx
A5: What was kept same
A6: - Existing sheet names and structure are unchanged.
A7: - Existing Delivery/Quality/Value computed formulas remain intact.
A9: What was added for full auto-fill demo
A10: - Proxy helper columns U:AB on Raw Delivery Log.
A11: - Extended summary rows B48:B62 on Raw Delivery Log.
A12: - Input metric cells in Delivery/Quality/Value link to Raw summary cells.
A14: Proxy assumptions (for manager review)
A15: - Scope/FORMAL/Automation/Initiative are derived by helper formulas from existing raw fields.
... A17: - These can be replaced later with actual explicit raw input columns if approved.
